[2025-09-19T11:16:08.693+0000] {local_task_job_runner.py:120} INFO - ::group::Pre task execution logs
[2025-09-19T11:16:08.740+0000] {taskinstance.py:2076} INFO - Dependencies all met for dep_context=non-requeueable deps ti=<TaskInstance: mayo_pipeline.validate_with_ge manual__2025-09-19T11:16:07.151018+00:00 [queued]>
[2025-09-19T11:16:08.761+0000] {taskinstance.py:2076} INFO - Dependencies all met for dep_context=requeueable deps ti=<TaskInstance: mayo_pipeline.validate_with_ge manual__2025-09-19T11:16:07.151018+00:00 [queued]>
[2025-09-19T11:16:08.762+0000] {taskinstance.py:2306} INFO - Starting attempt 1 of 1
[2025-09-19T11:16:08.781+0000] {taskinstance.py:2330} INFO - Executing <Task(BashOperator): validate_with_ge> on 2025-09-19 11:16:07.151018+00:00
[2025-09-19T11:16:08.787+0000] {standard_task_runner.py:63} INFO - Started process 371 to run task
[2025-09-19T11:16:08.792+0000] {standard_task_runner.py:90} INFO - Running: ['***', 'tasks', 'run', 'mayo_pipeline', 'validate_with_ge', 'manual__2025-09-19T11:16:07.151018+00:00', '--job-id', '4', '--raw', '--subdir', 'DAGS_FOLDER/mayo_pipeline.py', '--cfg-path', '/tmp/tmphir6uetw']
[2025-09-19T11:16:08.795+0000] {standard_task_runner.py:91} INFO - Job 4: Subtask validate_with_ge
[2025-09-19T11:16:08.858+0000] {task_command.py:426} INFO - Running <TaskInstance: mayo_pipeline.validate_with_ge manual__2025-09-19T11:16:07.151018+00:00 [running]> on host d93916f05490
[2025-09-19T11:16:09.078+0000] {taskinstance.py:2648} INFO - Exporting env vars: AIRFLOW_CTX_DAG_OWNER='you' AIRFLOW_CTX_DAG_ID='mayo_pipeline' AIRFLOW_CTX_TASK_ID='validate_with_ge' AIRFLOW_CTX_EXECUTION_DATE='2025-09-19T11:16:07.151018+00:00' AIRFLOW_CTX_TRY_NUMBER='1' AIRFLOW_CTX_DAG_RUN_ID='manual__2025-09-19T11:16:07.151018+00:00'
[2025-09-19T11:16:09.079+0000] {taskinstance.py:430} INFO - ::endgroup::
[2025-09-19T11:16:09.090+0000] {subprocess.py:63} INFO - Tmp dir root location: /tmp
[2025-09-19T11:16:09.091+0000] {subprocess.py:75} INFO - Running command: ['/usr/bin/bash', '-c', 'cd /opt/project && python validation/run_great_expectations.py']
[2025-09-19T11:16:09.103+0000] {subprocess.py:86} INFO - Output:
[2025-09-19T11:16:09.105+0000] {subprocess.py:93} INFO - /usr/bin/bash: line 1: cd: /opt/project: No such file or directory
[2025-09-19T11:16:09.105+0000] {subprocess.py:97} INFO - Command exited with return code 1
[2025-09-19T11:16:09.106+0000] {taskinstance.py:441} INFO - ::group::Post task execution logs
[2025-09-19T11:16:09.120+0000] {taskinstance.py:2905} ERROR - Task failed with exception
Traceback (most recent call last):
  File "/home/airflow/.local/lib/python3.11/site-packages/airflow/models/taskinstance.py", line 465, in _execute_task
    result = _execute_callable(context=context, **execute_callable_kwargs)
             ^^^^^^^^^^^^^^^^^^^^^^^^^^^^^^^^^^^^^^^^^^^^^^^^^^^^^^^^^^^^^
  File "/home/airflow/.local/lib/python3.11/site-packages/airflow/models/taskinstance.py", line 432, in _execute_callable
    return execute_callable(context=context, **execute_callable_kwargs)
           ^^^^^^^^^^^^^^^^^^^^^^^^^^^^^^^^^^^^^^^^^^^^^^^^^^^^^^^^^^^^
  File "/home/airflow/.local/lib/python3.11/site-packages/airflow/models/baseoperator.py", line 401, in wrapper
    return func(self, *args, **kwargs)
           ^^^^^^^^^^^^^^^^^^^^^^^^^^^
  File "/home/airflow/.local/lib/python3.11/site-packages/airflow/operators/bash.py", line 243, in execute
    raise AirflowException(
airflow.exceptions.AirflowException: Bash command failed. The command returned a non-zero exit code 1.
[2025-09-19T11:16:09.126+0000] {taskinstance.py:1206} INFO - Marking task as FAILED. dag_id=mayo_pipeline, task_id=validate_with_ge, run_id=manual__2025-09-19T11:16:07.151018+00:00, execution_date=20250919T111607, start_date=20250919T111608, end_date=20250919T111609
[2025-09-19T11:16:09.144+0000] {standard_task_runner.py:110} ERROR - Failed to execute job 4 for task validate_with_ge (Bash command failed. The command returned a non-zero exit code 1.; 371)
[2025-09-19T11:16:09.166+0000] {local_task_job_runner.py:240} INFO - Task exited with return code 1
[2025-09-19T11:16:09.187+0000] {taskinstance.py:3503} INFO - 0 downstream tasks scheduled from follow-on schedule check
[2025-09-19T11:16:09.191+0000] {local_task_job_runner.py:222} INFO - ::endgroup::
