[2025-09-19T14:54:39.601+0000] {local_task_job_runner.py:120} INFO - ::group::Pre task execution logs
[2025-09-19T14:54:39.641+0000] {taskinstance.py:2076} INFO - Dependencies all met for dep_context=non-requeueable deps ti=<TaskInstance: mayo_pipeline.validate_with_ge manual__2025-09-19T14:54:37.565938+00:00 [queued]>
[2025-09-19T14:54:39.650+0000] {taskinstance.py:2076} INFO - Dependencies all met for dep_context=requeueable deps ti=<TaskInstance: mayo_pipeline.validate_with_ge manual__2025-09-19T14:54:37.565938+00:00 [queued]>
[2025-09-19T14:54:39.658+0000] {taskinstance.py:2306} INFO - Starting attempt 1 of 1
[2025-09-19T14:54:39.670+0000] {taskinstance.py:2330} INFO - Executing <Task(BashOperator): validate_with_ge> on 2025-09-19 14:54:37.565938+00:00
[2025-09-19T14:54:39.675+0000] {standard_task_runner.py:63} INFO - Started process 190 to run task
[2025-09-19T14:54:39.678+0000] {standard_task_runner.py:90} INFO - Running: ['***', 'tasks', 'run', 'mayo_pipeline', 'validate_with_ge', 'manual__2025-09-19T14:54:37.565938+00:00', '--job-id', '4', '--raw', '--subdir', 'DAGS_FOLDER/mayo_pipeline.py', '--cfg-path', '/tmp/tmp9mxrrlo3']
[2025-09-19T14:54:39.681+0000] {standard_task_runner.py:91} INFO - Job 4: Subtask validate_with_ge
[2025-09-19T14:54:39.740+0000] {task_command.py:426} INFO - Running <TaskInstance: mayo_pipeline.validate_with_ge manual__2025-09-19T14:54:37.565938+00:00 [running]> on host ef28c6188499
[2025-09-19T14:54:39.949+0000] {taskinstance.py:2648} INFO - Exporting env vars: AIRFLOW_CTX_DAG_OWNER='you' AIRFLOW_CTX_DAG_ID='mayo_pipeline' AIRFLOW_CTX_TASK_ID='validate_with_ge' AIRFLOW_CTX_EXECUTION_DATE='2025-09-19T14:54:37.565938+00:00' AIRFLOW_CTX_TRY_NUMBER='1' AIRFLOW_CTX_DAG_RUN_ID='manual__2025-09-19T14:54:37.565938+00:00'
[2025-09-19T14:54:39.951+0000] {taskinstance.py:430} INFO - ::endgroup::
[2025-09-19T14:54:39.960+0000] {subprocess.py:63} INFO - Tmp dir root location: /tmp
[2025-09-19T14:54:39.961+0000] {subprocess.py:75} INFO - Running command: ['/usr/bin/bash', '-c', 'cd /opt/project && python validation/run_great_expectations.py']
[2025-09-19T14:54:39.970+0000] {subprocess.py:86} INFO - Output:
[2025-09-19T14:54:40.022+0000] {subprocess.py:93} INFO - python: can't open file '/opt/project/validation/run_great_expectations.py': [Errno 2] No such file or directory
[2025-09-19T14:54:40.025+0000] {subprocess.py:97} INFO - Command exited with return code 2
[2025-09-19T14:54:40.026+0000] {taskinstance.py:441} INFO - ::group::Post task execution logs
[2025-09-19T14:54:40.035+0000] {taskinstance.py:2905} ERROR - Task failed with exception
Traceback (most recent call last):
  File "/home/airflow/.local/lib/python3.11/site-packages/airflow/models/taskinstance.py", line 465, in _execute_task
    result = _execute_callable(context=context, **execute_callable_kwargs)
             ^^^^^^^^^^^^^^^^^^^^^^^^^^^^^^^^^^^^^^^^^^^^^^^^^^^^^^^^^^^^^
  File "/home/airflow/.local/lib/python3.11/site-packages/airflow/models/taskinstance.py", line 432, in _execute_callable
    return execute_callable(context=context, **execute_callable_kwargs)
           ^^^^^^^^^^^^^^^^^^^^^^^^^^^^^^^^^^^^^^^^^^^^^^^^^^^^^^^^^^^^
  File "/home/airflow/.local/lib/python3.11/site-packages/airflow/models/baseoperator.py", line 401, in wrapper
    return func(self, *args, **kwargs)
           ^^^^^^^^^^^^^^^^^^^^^^^^^^^
  File "/home/airflow/.local/lib/python3.11/site-packages/airflow/operators/bash.py", line 243, in execute
    raise AirflowException(
airflow.exceptions.AirflowException: Bash command failed. The command returned a non-zero exit code 2.
[2025-09-19T14:54:40.039+0000] {taskinstance.py:1206} INFO - Marking task as FAILED. dag_id=mayo_pipeline, task_id=validate_with_ge, run_id=manual__2025-09-19T14:54:37.565938+00:00, execution_date=20250919T145437, start_date=20250919T145439, end_date=20250919T145440
[2025-09-19T14:54:40.048+0000] {standard_task_runner.py:110} ERROR - Failed to execute job 4 for task validate_with_ge (Bash command failed. The command returned a non-zero exit code 2.; 190)
[2025-09-19T14:54:40.092+0000] {local_task_job_runner.py:240} INFO - Task exited with return code 1
[2025-09-19T14:54:40.111+0000] {taskinstance.py:3503} INFO - 0 downstream tasks scheduled from follow-on schedule check
[2025-09-19T14:54:40.116+0000] {local_task_job_runner.py:222} INFO - ::endgroup::
