[2025-09-19T15:05:11.671+0000] {local_task_job_runner.py:120} INFO - ::group::Pre task execution logs
[2025-09-19T15:05:11.705+0000] {taskinstance.py:2076} INFO - Dependencies all met for dep_context=non-requeueable deps ti=<TaskInstance: mayo_pipeline.etl_labs manual__2025-09-19T15:05:10.678452+00:00 [queued]>
[2025-09-19T15:05:11.714+0000] {taskinstance.py:2076} INFO - Dependencies all met for dep_context=requeueable deps ti=<TaskInstance: mayo_pipeline.etl_labs manual__2025-09-19T15:05:10.678452+00:00 [queued]>
[2025-09-19T15:05:11.715+0000] {taskinstance.py:2306} INFO - Starting attempt 1 of 1
[2025-09-19T15:05:11.728+0000] {taskinstance.py:2330} INFO - Executing <Task(BashOperator): etl_labs> on 2025-09-19 15:05:10.678452+00:00
[2025-09-19T15:05:11.733+0000] {standard_task_runner.py:63} INFO - Started process 186 to run task
[2025-09-19T15:05:11.737+0000] {standard_task_runner.py:90} INFO - Running: ['***', 'tasks', 'run', 'mayo_pipeline', 'etl_labs', 'manual__2025-09-19T15:05:10.678452+00:00', '--job-id', '3', '--raw', '--subdir', 'DAGS_FOLDER/mayo_pipeline.py', '--cfg-path', '/tmp/tmp8g8xctda']
[2025-09-19T15:05:11.741+0000] {standard_task_runner.py:91} INFO - Job 3: Subtask etl_labs
[2025-09-19T15:05:11.816+0000] {task_command.py:426} INFO - Running <TaskInstance: mayo_pipeline.etl_labs manual__2025-09-19T15:05:10.678452+00:00 [running]> on host aae1d613763d
[2025-09-19T15:05:12.120+0000] {taskinstance.py:2648} INFO - Exporting env vars: AIRFLOW_CTX_DAG_OWNER='you' AIRFLOW_CTX_DAG_ID='mayo_pipeline' AIRFLOW_CTX_TASK_ID='etl_labs' AIRFLOW_CTX_EXECUTION_DATE='2025-09-19T15:05:10.678452+00:00' AIRFLOW_CTX_TRY_NUMBER='1' AIRFLOW_CTX_DAG_RUN_ID='manual__2025-09-19T15:05:10.678452+00:00'
[2025-09-19T15:05:12.121+0000] {taskinstance.py:430} INFO - ::endgroup::
[2025-09-19T15:05:12.149+0000] {subprocess.py:63} INFO - Tmp dir root location: /tmp
[2025-09-19T15:05:12.150+0000] {subprocess.py:75} INFO - Running command: ['/usr/bin/bash', '-c', "/bin/bash -lc 'set -euo pipefail; python /opt/project/etl/flatten_mimic_labs.py'"]
[2025-09-19T15:05:12.159+0000] {subprocess.py:86} INFO - Output:
[2025-09-19T15:05:13.871+0000] {subprocess.py:93} INFO - Traceback (most recent call last):
[2025-09-19T15:05:13.872+0000] {subprocess.py:93} INFO -   File "/opt/project/etl/flatten_mimic_labs.py", line 67, in <module>
[2025-09-19T15:05:13.875+0000] {subprocess.py:93} INFO -     main()
[2025-09-19T15:05:13.875+0000] {subprocess.py:93} INFO -   File "/opt/project/etl/flatten_mimic_labs.py", line 44, in main
[2025-09-19T15:05:13.878+0000] {subprocess.py:93} INFO -     df = pd.read_csv(SRC, nrows=NROWS)
[2025-09-19T15:05:13.878+0000] {subprocess.py:93} INFO -          ^^^^^^^^^^^^^^^^^^^^^^^^^^^^^
[2025-09-19T15:05:13.879+0000] {subprocess.py:93} INFO -   File "/home/***/.local/lib/python3.11/site-packages/pandas/io/parsers/readers.py", line 948, in read_csv
[2025-09-19T15:05:13.879+0000] {subprocess.py:93} INFO -     return _read(filepath_or_buffer, kwds)
[2025-09-19T15:05:13.879+0000] {subprocess.py:93} INFO -            ^^^^^^^^^^^^^^^^^^^^^^^^^^^^^^^
[2025-09-19T15:05:13.880+0000] {subprocess.py:93} INFO -   File "/home/***/.local/lib/python3.11/site-packages/pandas/io/parsers/readers.py", line 611, in _read
[2025-09-19T15:05:13.880+0000] {subprocess.py:93} INFO -     parser = TextFileReader(filepath_or_buffer, **kwds)
[2025-09-19T15:05:13.880+0000] {subprocess.py:93} INFO -              ^^^^^^^^^^^^^^^^^^^^^^^^^^^^^^^^^^^^^^^^^^
[2025-09-19T15:05:13.880+0000] {subprocess.py:93} INFO -   File "/home/***/.local/lib/python3.11/site-packages/pandas/io/parsers/readers.py", line 1448, in __init__
[2025-09-19T15:05:13.881+0000] {subprocess.py:93} INFO -     self._engine = self._make_engine(f, self.engine)
[2025-09-19T15:05:13.881+0000] {subprocess.py:93} INFO -                    ^^^^^^^^^^^^^^^^^^^^^^^^^^^^^^^^^
[2025-09-19T15:05:13.881+0000] {subprocess.py:93} INFO -   File "/home/***/.local/lib/python3.11/site-packages/pandas/io/parsers/readers.py", line 1705, in _make_engine
[2025-09-19T15:05:13.881+0000] {subprocess.py:93} INFO -     self.handles = get_handle(
[2025-09-19T15:05:13.882+0000] {subprocess.py:93} INFO -                    ^^^^^^^^^^^
[2025-09-19T15:05:13.882+0000] {subprocess.py:93} INFO -   File "/home/***/.local/lib/python3.11/site-packages/pandas/io/common.py", line 863, in get_handle
[2025-09-19T15:05:13.883+0000] {subprocess.py:93} INFO -     handle = open(
[2025-09-19T15:05:13.883+0000] {subprocess.py:93} INFO -              ^^^^^
[2025-09-19T15:05:13.883+0000] {subprocess.py:93} INFO - FileNotFoundError: [Errno 2] No such file or directory: 'data/labs_raw.csv'
[2025-09-19T15:05:13.981+0000] {subprocess.py:97} INFO - Command exited with return code 1
[2025-09-19T15:05:13.982+0000] {taskinstance.py:441} INFO - ::group::Post task execution logs
[2025-09-19T15:05:13.991+0000] {taskinstance.py:2905} ERROR - Task failed with exception
Traceback (most recent call last):
  File "/home/airflow/.local/lib/python3.11/site-packages/airflow/models/taskinstance.py", line 465, in _execute_task
    result = _execute_callable(context=context, **execute_callable_kwargs)
             ^^^^^^^^^^^^^^^^^^^^^^^^^^^^^^^^^^^^^^^^^^^^^^^^^^^^^^^^^^^^^
  File "/home/airflow/.local/lib/python3.11/site-packages/airflow/models/taskinstance.py", line 432, in _execute_callable
    return execute_callable(context=context, **execute_callable_kwargs)
           ^^^^^^^^^^^^^^^^^^^^^^^^^^^^^^^^^^^^^^^^^^^^^^^^^^^^^^^^^^^^
  File "/home/airflow/.local/lib/python3.11/site-packages/airflow/models/baseoperator.py", line 401, in wrapper
    return func(self, *args, **kwargs)
           ^^^^^^^^^^^^^^^^^^^^^^^^^^^
  File "/home/airflow/.local/lib/python3.11/site-packages/airflow/operators/bash.py", line 243, in execute
    raise AirflowException(
airflow.exceptions.AirflowException: Bash command failed. The command returned a non-zero exit code 1.
[2025-09-19T15:05:13.995+0000] {taskinstance.py:1206} INFO - Marking task as FAILED. dag_id=mayo_pipeline, task_id=etl_labs, run_id=manual__2025-09-19T15:05:10.678452+00:00, execution_date=20250919T150510, start_date=20250919T150511, end_date=20250919T150513
[2025-09-19T15:05:14.006+0000] {standard_task_runner.py:110} ERROR - Failed to execute job 3 for task etl_labs (Bash command failed. The command returned a non-zero exit code 1.; 186)
[2025-09-19T15:05:14.039+0000] {local_task_job_runner.py:240} INFO - Task exited with return code 1
[2025-09-19T15:05:14.047+0000] {local_task_job_runner.py:222} INFO - ::endgroup::
