[2025-09-19T16:28:15.676+0000] {local_task_job_runner.py:120} INFO - ::group::Pre task execution logs
[2025-09-19T16:28:15.709+0000] {taskinstance.py:2076} INFO - Dependencies all met for dep_context=non-requeueable deps ti=<TaskInstance: mayo_pipeline.etl_labs manual__2025-09-19T16:28:14.419646+00:00 [queued]>
[2025-09-19T16:28:15.717+0000] {taskinstance.py:2076} INFO - Dependencies all met for dep_context=requeueable deps ti=<TaskInstance: mayo_pipeline.etl_labs manual__2025-09-19T16:28:14.419646+00:00 [queued]>
[2025-09-19T16:28:15.718+0000] {taskinstance.py:2306} INFO - Starting attempt 1 of 1
[2025-09-19T16:28:15.731+0000] {taskinstance.py:2330} INFO - Executing <Task(BashOperator): etl_labs> on 2025-09-19 16:28:14.419646+00:00
[2025-09-19T16:28:15.736+0000] {standard_task_runner.py:63} INFO - Started process 186 to run task
[2025-09-19T16:28:15.741+0000] {standard_task_runner.py:90} INFO - Running: ['***', 'tasks', 'run', 'mayo_pipeline', 'etl_labs', 'manual__2025-09-19T16:28:14.419646+00:00', '--job-id', '2', '--raw', '--subdir', 'DAGS_FOLDER/mayo_pipeline.py', '--cfg-path', '/tmp/tmpe3o1u09b']
[2025-09-19T16:28:15.744+0000] {standard_task_runner.py:91} INFO - Job 2: Subtask etl_labs
[2025-09-19T16:28:15.818+0000] {task_command.py:426} INFO - Running <TaskInstance: mayo_pipeline.etl_labs manual__2025-09-19T16:28:14.419646+00:00 [running]> on host ff389c3b28cc
[2025-09-19T16:28:15.911+0000] {taskinstance.py:2648} INFO - Exporting env vars: AIRFLOW_CTX_DAG_OWNER='you' AIRFLOW_CTX_DAG_ID='mayo_pipeline' AIRFLOW_CTX_TASK_ID='etl_labs' AIRFLOW_CTX_EXECUTION_DATE='2025-09-19T16:28:14.419646+00:00' AIRFLOW_CTX_TRY_NUMBER='1' AIRFLOW_CTX_DAG_RUN_ID='manual__2025-09-19T16:28:14.419646+00:00'
[2025-09-19T16:28:15.912+0000] {taskinstance.py:430} INFO - ::endgroup::
[2025-09-19T16:28:15.949+0000] {subprocess.py:63} INFO - Tmp dir root location: /tmp
[2025-09-19T16:28:15.950+0000] {subprocess.py:75} INFO - Running command: ['/usr/bin/bash', '-c', "/bin/bash -lc 'set -euo pipefail; cd /opt/project && python etl/flatten_mimic_labs.py'"]
[2025-09-19T16:28:15.960+0000] {subprocess.py:86} INFO - Output:
[2025-09-19T16:28:17.840+0000] {subprocess.py:93} INFO - Traceback (most recent call last):
[2025-09-19T16:28:17.840+0000] {subprocess.py:93} INFO -   File "/opt/project/etl/flatten_mimic_labs.py", line 36, in <module>
[2025-09-19T16:28:17.842+0000] {subprocess.py:93} INFO -     main()
[2025-09-19T16:28:17.843+0000] {subprocess.py:93} INFO -   File "/opt/project/etl/flatten_mimic_labs.py", line 14, in main
[2025-09-19T16:28:17.844+0000] {subprocess.py:93} INFO -     raise FileNotFoundError(
[2025-09-19T16:28:17.845+0000] {subprocess.py:93} INFO - FileNotFoundError: Expected file not found: /opt/project/data/physionet.org/files/mimic-iv-demo/2.2/hosp/labevents.csv.gz
[2025-09-19T16:28:17.845+0000] {subprocess.py:93} INFO - Download the MIMIC-IV *demo* (not ED) hosp/labevents.csv.gz under data/physionet.org/files/mimic-iv-demo/2.2/hosp/
[2025-09-19T16:28:17.922+0000] {subprocess.py:97} INFO - Command exited with return code 1
[2025-09-19T16:28:17.923+0000] {taskinstance.py:441} INFO - ::group::Post task execution logs
[2025-09-19T16:28:18.067+0000] {taskinstance.py:2905} ERROR - Task failed with exception
Traceback (most recent call last):
  File "/home/airflow/.local/lib/python3.11/site-packages/airflow/models/taskinstance.py", line 465, in _execute_task
    result = _execute_callable(context=context, **execute_callable_kwargs)
             ^^^^^^^^^^^^^^^^^^^^^^^^^^^^^^^^^^^^^^^^^^^^^^^^^^^^^^^^^^^^^
  File "/home/airflow/.local/lib/python3.11/site-packages/airflow/models/taskinstance.py", line 432, in _execute_callable
    return execute_callable(context=context, **execute_callable_kwargs)
           ^^^^^^^^^^^^^^^^^^^^^^^^^^^^^^^^^^^^^^^^^^^^^^^^^^^^^^^^^^^^
  File "/home/airflow/.local/lib/python3.11/site-packages/airflow/models/baseoperator.py", line 401, in wrapper
    return func(self, *args, **kwargs)
           ^^^^^^^^^^^^^^^^^^^^^^^^^^^
  File "/home/airflow/.local/lib/python3.11/site-packages/airflow/operators/bash.py", line 243, in execute
    raise AirflowException(
airflow.exceptions.AirflowException: Bash command failed. The command returned a non-zero exit code 1.
[2025-09-19T16:28:18.071+0000] {taskinstance.py:1206} INFO - Marking task as FAILED. dag_id=mayo_pipeline, task_id=etl_labs, run_id=manual__2025-09-19T16:28:14.419646+00:00, execution_date=20250919T162814, start_date=20250919T162815, end_date=20250919T162818
[2025-09-19T16:28:18.082+0000] {standard_task_runner.py:110} ERROR - Failed to execute job 2 for task etl_labs (Bash command failed. The command returned a non-zero exit code 1.; 186)
[2025-09-19T16:28:18.129+0000] {local_task_job_runner.py:240} INFO - Task exited with return code 1
[2025-09-19T16:28:18.150+0000] {taskinstance.py:3503} INFO - 0 downstream tasks scheduled from follow-on schedule check
[2025-09-19T16:28:18.156+0000] {local_task_job_runner.py:222} INFO - ::endgroup::
