[2025-09-19T14:44:41.706+0000] {local_task_job_runner.py:120} INFO - ::group::Pre task execution logs
[2025-09-19T14:44:41.745+0000] {taskinstance.py:2076} INFO - Dependencies all met for dep_context=non-requeueable deps ti=<TaskInstance: mayo_pipeline.validate_with_ge manual__2025-09-19T14:44:39.624469+00:00 [queued]>
[2025-09-19T14:44:41.752+0000] {taskinstance.py:2076} INFO - Dependencies all met for dep_context=requeueable deps ti=<TaskInstance: mayo_pipeline.validate_with_ge manual__2025-09-19T14:44:39.624469+00:00 [queued]>
[2025-09-19T14:44:41.760+0000] {taskinstance.py:2306} INFO - Starting attempt 1 of 1
[2025-09-19T14:44:41.772+0000] {taskinstance.py:2330} INFO - Executing <Task(BashOperator): validate_with_ge> on 2025-09-19 14:44:39.624469+00:00
[2025-09-19T14:44:41.777+0000] {standard_task_runner.py:63} INFO - Started process 191 to run task
[2025-09-19T14:44:41.780+0000] {standard_task_runner.py:90} INFO - Running: ['***', 'tasks', 'run', 'mayo_pipeline', 'validate_with_ge', 'manual__2025-09-19T14:44:39.624469+00:00', '--job-id', '4', '--raw', '--subdir', 'DAGS_FOLDER/mayo_pipeline.py', '--cfg-path', '/tmp/tmpex_5zq_7']
[2025-09-19T14:44:41.782+0000] {standard_task_runner.py:91} INFO - Job 4: Subtask validate_with_ge
[2025-09-19T14:44:41.844+0000] {task_command.py:426} INFO - Running <TaskInstance: mayo_pipeline.validate_with_ge manual__2025-09-19T14:44:39.624469+00:00 [running]> on host 079e61bbc317
[2025-09-19T14:44:42.060+0000] {taskinstance.py:2648} INFO - Exporting env vars: AIRFLOW_CTX_DAG_OWNER='you' AIRFLOW_CTX_DAG_ID='mayo_pipeline' AIRFLOW_CTX_TASK_ID='validate_with_ge' AIRFLOW_CTX_EXECUTION_DATE='2025-09-19T14:44:39.624469+00:00' AIRFLOW_CTX_TRY_NUMBER='1' AIRFLOW_CTX_DAG_RUN_ID='manual__2025-09-19T14:44:39.624469+00:00'
[2025-09-19T14:44:42.061+0000] {taskinstance.py:430} INFO - ::endgroup::
[2025-09-19T14:44:42.070+0000] {subprocess.py:63} INFO - Tmp dir root location: /tmp
[2025-09-19T14:44:42.071+0000] {subprocess.py:75} INFO - Running command: ['/usr/bin/bash', '-c', 'cd /opt/project && python validation/run_great_expectations.py']
[2025-09-19T14:44:42.079+0000] {subprocess.py:86} INFO - Output:
[2025-09-19T14:44:42.132+0000] {subprocess.py:93} INFO - python: can't open file '/opt/project/validation/run_great_expectations.py': [Errno 2] No such file or directory
[2025-09-19T14:44:42.135+0000] {subprocess.py:97} INFO - Command exited with return code 2
[2025-09-19T14:44:42.136+0000] {taskinstance.py:441} INFO - ::group::Post task execution logs
[2025-09-19T14:44:42.145+0000] {taskinstance.py:2905} ERROR - Task failed with exception
Traceback (most recent call last):
  File "/home/airflow/.local/lib/python3.11/site-packages/airflow/models/taskinstance.py", line 465, in _execute_task
    result = _execute_callable(context=context, **execute_callable_kwargs)
             ^^^^^^^^^^^^^^^^^^^^^^^^^^^^^^^^^^^^^^^^^^^^^^^^^^^^^^^^^^^^^
  File "/home/airflow/.local/lib/python3.11/site-packages/airflow/models/taskinstance.py", line 432, in _execute_callable
    return execute_callable(context=context, **execute_callable_kwargs)
           ^^^^^^^^^^^^^^^^^^^^^^^^^^^^^^^^^^^^^^^^^^^^^^^^^^^^^^^^^^^^
  File "/home/airflow/.local/lib/python3.11/site-packages/airflow/models/baseoperator.py", line 401, in wrapper
    return func(self, *args, **kwargs)
           ^^^^^^^^^^^^^^^^^^^^^^^^^^^
  File "/home/airflow/.local/lib/python3.11/site-packages/airflow/operators/bash.py", line 243, in execute
    raise AirflowException(
airflow.exceptions.AirflowException: Bash command failed. The command returned a non-zero exit code 2.
[2025-09-19T14:44:42.149+0000] {taskinstance.py:1206} INFO - Marking task as FAILED. dag_id=mayo_pipeline, task_id=validate_with_ge, run_id=manual__2025-09-19T14:44:39.624469+00:00, execution_date=20250919T144439, start_date=20250919T144441, end_date=20250919T144442
[2025-09-19T14:44:42.160+0000] {standard_task_runner.py:110} ERROR - Failed to execute job 4 for task validate_with_ge (Bash command failed. The command returned a non-zero exit code 2.; 191)
[2025-09-19T14:44:42.194+0000] {local_task_job_runner.py:240} INFO - Task exited with return code 1
[2025-09-19T14:44:42.213+0000] {taskinstance.py:3503} INFO - 0 downstream tasks scheduled from follow-on schedule check
[2025-09-19T14:44:42.218+0000] {local_task_job_runner.py:222} INFO - ::endgroup::
